Workbook

Sheet Sheet1
A4: Bum | B4: Sum of Avg Win Total | C4: Sum of SD | D4: Sum of Rank | E4: Sum of Pick Analysis | F4: https://www.eldo.co/analysis/your-nfl-wins-pool-draft-order-needs-some-adjusting
A5: Flaim | B5: 27.29671 | C5: 2.9732033 | D5: 43 | E5: 3
A6: Bailey | B6: 27.26107 | C6: 2.4648227 | D6: 41 | E6: 1
A7: Rubino | B7: 27.07099 | C7: 2.2989053 | D7: 42 | E7: -1
A8: Matt M | B8: 26.90297 | C8: 2.2817561 | D8: 44 | E8: 1
A9: Brad | B9: 26.77907 | C9: 2.5568189 | D9: 42 | E9: 3
A10: Fish | B10: 26.22588 | C10: 2.3038181 | D10: 45 | E10: 1
A11: Chris M | B11: 26.0369 | C11: 2.7135743 | D11: 46 | E11: 1
A12: Avallone | B12: 25.63636 | C12: 3.0899715 | D12: 49 | E12: -1
A13: Otto | B13: 24.28927 | C13: 2.0831992 | D13: 55 | E13: -1
A14: Conley | B14: 24.06052 | C14: 2.6826359 | D14: 58 | E14: -1

Sheet Draft
G1: 2 | H1: =G1+1 -> 3 | I1: =H1+1 -> 4 | J1: =I1+1 -> 5 | K1: =J1+1 -> 6 | L1: =K1+1 -> 7 | M1: =L1+1 -> 8 | N1: =M1+1 -> 9 | O1: =N1+1 -> 10 | ... R1: =Q1+1 -> 13 | S1: 14 | T1: 15 | U1: 16
A2: Draft Pick | B2: Guy | D2: Pick | E2: Bum | F2: Team | G2: BR | H2: FPI | I2: SI | J2: ESPN | K2: CBS | L2: Athletic | M2: PFF | N2: NFL | O2: O/U | P2: Clay | Q2: Avg Win Total | R2: SD | S2: Z Score | T2: Z Test | U2: Rank | V2: Pick Analysis | W2: Pick Diff | X2: PlayerID | Y2: T1 | Z2: Column2
A3: 1 | B3: Otto | D3: 1 | E3: =VLOOKUP(1,Draft!$A$2:$B$12,2,FALSE) -> Otto | F3: Kansas City Chiefs | G3: =VLOOKUP($F3,$F$41:$U$72,G$1,FALSE) -> 11 | H3: =VLOOKUP($F3,$F$41:$U$72,H$1,FALSE) -> 10.4 | I3: =VLOOKUP($F3,$F$41:$U$72,I$1,FALSE) -> 11 | J3: =VLOOKUP($F3,$F$41:$U$72,J$1,FALSE) -> 13 | K3: =VLOOKUP($F3,$F$41:$U$72,K$1,FALSE) -> 12 | L3: =VLOOKUP($F3,$F$41:$U$72,L$1,FALSE) -> 11.3 | M3: =VLOOKUP($F3,$F$41:$U$72,M$1,FALSE) -> 10.9056 | N3: =VLOOKUP($F3,$F$41:$U$72,N$1,FALSE) -> 11.4 | ... U3: =VLOOKUP($F3,$F$41:$U$72,U$1,FALSE) -> 1 | V3: =IF(Table2[[#This Row],[Pick]]>=Table2[[#This Row],[Rank]],1,-1) -> 1 | W3: =Table2[[#This Row],[Pick]]-Table2[[#This Row],[Rank]] -> 0 | X3: 6 | Y3: KC | Z3: ="2024,"&Table2[[#This Row],[Pick]]&","&Table2[[#This Row],[PlayerID]]&","&Table2[[#This Row],[T1]] -> 2024,1,6,KC
A4: 2 | B4: Conley | D4: 2 | E4: =VLOOKUP(2,Draft!$A$2:$B$12,2,FALSE) -> Conley | F4: Dallas Cowboys | G4: =VLOOKUP($F4,$F$41:$U$72,G$1,FALSE) -> 8 | H4: =VLOOKUP($F4,$F$41:$U$72,H$1,FALSE) -> 9.5 | I4: =VLOOKUP($F4,$F$41:$U$72,I$1,FALSE) -> 9 | J4: =VLOOKUP($F4,$F$41:$U$72,J$1,FALSE) -> 11 | K4: =VLOOKUP($F4,$F$41:$U$72,K$1,FALSE) -> 10 | L4: =VLOOKUP($F4,$F$41:$U$72,L$1,FALSE) -> 10 | M4: =VLOOKUP($F4,$F$41:$U$72,M$1,FALSE) -> 9.604 | N4: =VLOOKUP($F4,$F$41:$U$72,N$1,FALSE) -> 9.2 | ... U4: =VLOOKUP($F4,$F$41:$U$72,U$1,FALSE) -> 10 | V4: =IF(Table2[[#This Row],[Pick]]>=Table2[[#This Row],[Rank]],1,-1) -> -1 | W4: =Table2[[#This Row],[Pick]]-Table2[[#This Row],[Rank]] -> -8 | X4: 8 | Y4: DAL | Z4: ="2024,"&Table2[[#This Row],[Pick]]&","&Table2[[#This Row],[PlayerID]]&","&Table2[[#This Row],[T1]] -> 2024,2,8,DAL
A5: 3 | B5: Brad | D5: 3 | E5: =VLOOKUP(3,Draft!$A$2:$B$12,2,FALSE) -> Brad | F5: San Francisco 49ers | G5: =VLOOKUP($F5,$F$41:$U$72,G$1,FALSE) -> 11 | H5: =VLOOKUP($F5,$F$41:$U$72,H$1,FALSE) -> 10.4 | I5: =VLOOKUP($F5,$F$41:$U$72,I$1,FALSE) -> 10 | J5: =VLOOKUP($F5,$F$41:$U$72,J$1,FALSE) -> 10 | K5: =VLOOKUP($F5,$F$41:$U$72,K$1,FALSE) -> 11 | L5: =VLOOKUP($F5,$F$41:$U$72,L$1,FALSE) -> 11.4 | M5: =VLOOKUP($F5,$F$41:$U$72,M$1,FALSE) -> 10.6623 | N5: =VLOOKUP($F5,$F$41:$U$72,N$1,FALSE) -> 11 | ... U5: =VLOOKUP($F5,$F$41:$U$72,U$1,FALSE) -> 3 | V5: =IF(Table2[[#This Row],[Pick]]>=Table2[[#This Row],[Rank]],1,-1) -> 1 | W5: =Table2[[#This Row],[Pick]]-Table2[[#This Row],[Rank]] -> 0 | X5: 3 | Y5: SF | Z5: ="2024,"&Table2[[#This Row],[Pick]]&","&Table2[[#This Row],[PlayerID]]&","&Table2[[#This Row],[T1]] -> 2024,3,3,SF
A6: 4 | B6: Flaim | D6: 4 | E6: =VLOOKUP(4,Draft!$A$2:$B$12,2,FALSE) -> Flaim | F6: Detroit Lions | G6: =VLOOKUP($F6,$F$41:$U$72,G$1,FALSE) -> 13 | H6: =VLOOKUP($F6,$F$41:$U$72,H$1,FALSE) -> 9.9 | I6: =VLOOKUP($F6,$F$41:$U$72,I$1,FALSE) -> 12 | J6: =VLOOKUP($F6,$F$41:$U$72,J$1,FALSE) -> 13 | K6: =VLOOKUP($F6,$F$41:$U$72,K$1,FALSE) -> 12 | L6: =VLOOKUP($F6,$F$41:$U$72,L$1,FALSE) -> 10.5 | M6: =VLOOKUP($F6,$F$41:$U$72,M$1,FALSE) -> 9.7087 | N6: =VLOOKUP($F6,$F$41:$U$72,N$1,FALSE) -> 10.7 | ... U6: =VLOOKUP($F6,$F$41:$U$72,U$1,FALSE) -> 2 | V6: =IF(Table2[[#This Row],[Pick]]>=Table2[[#This Row],[Rank]],1,-1) -> 1 | W6: =Table2[[#This Row],[Pick]]-Table2[[#This Row],[Rank]] -> 2 | X6: 7 | Y6: DET | Z6: ="2024,"&Table2[[#This Row],[Pick]]&","&Table2[[#This Row],[PlayerID]]&","&Table2[[#This Row],[T1]] -> 2024,4,7,DET
A7: 5 | B7: Fish | D7: 5 | E7: =VLOOKUP(5,Draft!$A$2:$B$12,2,FALSE) -> Fish | F7: Baltimore Ravens | G7: =VLOOKUP($F7,$F$41:$U$72,G$1,FALSE) -> 11 | H7: =VLOOKUP($F7,$F$41:$U$72,H$1,FALSE) -> 9.7 | I7: =VLOOKUP($F7,$F$41:$U$72,I$1,FALSE) -> 10 | J7: =VLOOKUP($F7,$F$41:$U$72,J$1,FALSE) -> 11 | K7: =VLOOKUP($F7,$F$41:$U$72,K$1,FALSE) -> 12 | L7: =VLOOKUP($F7,$F$41:$U$72,L$1,FALSE) -> 10.2 | M7: =VLOOKUP($F7,$F$41:$U$72,M$1,FALSE) -> 10.2175 | N7: =VLOOKUP($F7,$F$41:$U$72,N$1,FALSE) -> 10.5 | ... U7: =VLOOKUP($F7,$F$41:$U$72,U$1,FALSE) -> 4 | V7: =IF(Table2[[#This Row],[Pick]]>=Table2[[#This Row],[Rank]],1,-1) -> 1 | W7: =Table2[[#This Row],[Pick]]-Table2[[#This Row],[Rank]] -> 1 | X7: 1 | Y7: BAL | Z7: ="2024,"&Table2[[#This Row],[Pick]]&","&Table2[[#This Row],[PlayerID]]&","&Table2[[#This Row],[T1]] -> 2024,5,1,BAL
A8: 6 | B8: Rubino | D8: 6 | E8: =VLOOKUP(6,Draft!$A$2:$B$12,2,FALSE) -> Rubino | F8: Green Bay Packers | G8: =VLOOKUP($F8,$F$41:$U$72,G$1,FALSE) -> 10 | H8: =VLOOKUP($F8,$F$41:$U$72,H$1,FALSE) -> 9.2 | I8: =VLOOKUP($F8,$F$41:$U$72,I$1,FALSE) -> 12 | J8: =VLOOKUP($F8,$F$41:$U$72,J$1,FALSE) -> 11 | K8: =VLOOKUP($F8,$F$41:$U$72,K$1,FALSE) -> 11 | L8: =VLOOKUP($F8,$F$41:$U$72,L$1,FALSE) -> 9.8 | M8: =VLOOKUP($F8,$F$41:$U$72,M$1,FALSE) -> 9.2241 | N8: =VLOOKUP($F8,$F$41:$U$72,N$1,FALSE) -> 9.8 | ... U8: =VLOOKUP($F8,$F$41:$U$72,U$1,FALSE) -> 7 | V8: =IF(Table2[[#This Row],[Pick]]>=Table2[[#This Row],[Rank]],1,-1) -> -1 | W8: =Table2[[#This Row],[Pick]]-Table2[[#This Row],[Rank]] -> -1 | X8: 9 | Y8: GB | Z8: ="2024,"&Table2[[#This Row],[Pick]]&","&Table2[[#This Row],[PlayerID]]&","&Table2[[#This Row],[T1]] -> 2024,6,9,GB
A9: 7 | B9: Chris M | D9: 7 | E9: =VLOOKUP(7,Draft!$A$2:$B$12,2,FALSE) -> Chris M | F9: New York Jets | G9: =VLOOKUP($F9,$F$41:$U$72,G$1,FALSE) -> 10 | H9: =VLOOKUP($F9,$F$41:$U$72,H$1,FALSE) -> 9.3 | I9: =VLOOKUP($F9,$F$41:$U$72,I$1,FALSE) -> 9 | J9: =VLOOKUP($F9,$F$41:$U$72,J$1,FALSE) -> 12 | K9: =VLOOKUP($F9,$F$41:$U$72,K$1,FALSE) -> 10 | L9: =VLOOKUP($F9,$F$41:$U$72,L$1,FALSE) -> 9.6 | M9: =VLOOKUP($F9,$F$41:$U$72,M$1,FALSE) -> 9.0349 | N9: =VLOOKUP($F9,$F$41:$U$72,N$1,FALSE) -> 10.1 | ... U9: =VLOOKUP($F9,$F$41:$U$72,U$1,FALSE) -> 8 | V9: =IF(Table2[[#This Row],[Pick]]>=Table2[[#This Row],[Rank]],1,-1) -> -1 | W9: =Table2[[#This Row],[Pick]]-Table2[[#This Row],[Rank]] -> -1 | X9: 2 | Y9: NYJ | Z9: ="2024,"&Table2[[#This Row],[Pick]]&","&Table2[[#This Row],[PlayerID]]&","&Table2[[#This Row],[T1]] -> 2024,7,2,NYJ
A10: 8 | B10: Matt M | D10: 8 | E10: =VLOOKUP(8,Draft!$A$2:$B$12,2,FALSE) -> Matt M | F10: Philadelphia Eagles | G10: =VLOOKUP($F10,$F$41:$U$72,G$1,FALSE) -> 12 | H10: =VLOOKUP($F10,$F$41:$U$72,H$1,FALSE) -> 10.3 | I10: =VLOOKUP($F10,$F$41:$U$72,I$1,FALSE) -> 10 | J10: =VLOOKUP($F10,$F$41:$U$72,J$1,FALSE) -> 11 | K10: =VLOOKUP($F10,$F$41:$U$72,K$1,FALSE) -> 9 | L10: =VLOOKUP($F10,$F$41:$U$72,L$1,FALSE) -> 10.2 | M10: =VLOOKUP($F10,$F$41:$U$72,M$1,FALSE) -> 9.7891 | N10: =VLOOKUP($F10,$F$41:$U$72,N$1,FALSE) -> 11.2 | ... U10: =VLOOKUP($F10,$F$41:$U$72,U$1,FALSE) -> 6 | V10: =IF(Table2[[#This Row],[Pick]]>=Table2[[#This Row],[Rank]],1,-1) -> 1 | W10: =Table2[[#This Row],[Pick]]-Table2[[#This Row],[Rank]] -> 2 | X10: 4 | Y10: PHI | Z10: ="2024,"&Table2[[#This Row],[Pick]]&","&Table2[[#This Row],[PlayerID]]&","&Table2[[#This Row],[T1]] -> 2024,8,4,PHI
A11: 9 | B11: Avallone | D11: 9 | E11: =VLOOKUP(9,Draft!$A$2:$B$12,2,FALSE) -> Avallone | F11: Buffalo Bills | G11: =VLOOKUP($F11,$F$41:$U$72,G$1,FALSE) -> 9 | H11: =VLOOKUP($F11,$F$41:$U$72,H$1,FALSE) -> 9.4 | I11: =VLOOKUP($F11,$F$41:$U$72,I$1,FALSE) -> 10 | J11: =VLOOKUP($F11,$F$41:$U$72,J$1,FALSE) -> 7 | K11: =VLOOKUP($F11,$F$41:$U$72,K$1,FALSE) -> 9 | L11: =VLOOKUP($F11,$F$41:$U$72,L$1,FALSE) -> 9.7 | M11: =VLOOKUP($F11,$F$41:$U$72,M$1,FALSE) -> 9.723 | N11: =VLOOKUP($F11,$F$41:$U$72,N$1,FALSE) -> 10.1 | ... U11: =VLOOKUP($F11,$F$41:$U$72,U$1,FALSE) -> 12 | V11: =IF(Table2[[#This Row],[Pick]]>=Table2[[#This Row],[Rank]],1,-1) -> -1 | W11: =Table2[[#This Row],[Pick]]-Table2[[#This Row],[Rank]] -> -3 | X11: 5 | Y11: BUF | Z11: ="2024,"&Table2[[#This Row],[Pick]]&","&Table2[[#This Row],[PlayerID]]&","&Table2[[#This Row],[T1]] -> 2024,9,5,BUF
A12: 10 | B12: Bailey | D12: 10 | E12: =VLOOKUP(10,Draft!$A$2:$B$12,2,FALSE) -> Bailey | F12: Cincinnati Bengals | G12: =VLOOKUP($F12,$F$41:$U$72,G$1,FALSE) -> 11 | H12: =VLOOKUP($F12,$F$41:$U$72,H$1,FALSE) -> 9.8 | I12: =VLOOKUP($F12,$F$41:$U$72,I$1,FALSE) -> 11 | J12: =VLOOKUP($F12,$F$41:$U$72,J$1,FALSE) -> 11 | K12: =VLOOKUP($F12,$F$41:$U$72,K$1,FALSE) -> 11 | L12: =VLOOKUP($F12,$F$41:$U$72,L$1,FALSE) -> 10.2 | M12: =VLOOKUP($F12,$F$41:$U$72,M$1,FALSE) -> 9.7654 | N12: =VLOOKUP($F12,$F$41:$U$72,N$1,FALSE) -> 10.4 | ... U12: =VLOOKUP($F12,$F$41:$U$72,U$1,FALSE) -> 5 | V12: =IF(Table2[[#This Row],[Pick]]>=Table2[[#This Row],[Rank]],1,-1) -> 1 | W12: =Table2[[#This Row],[Pick]]-Table2[[#This Row],[Rank]] -> 5 | X12: 10 | Y12: CIN | Z12: ="2024,"&Table2[[#This Row],[Pick]]&","&Table2[[#This Row],[PlayerID]]&","&Table2[[#This Row],[T1]] -> 2024,10,10,CIN
D13: 11 | E13: =VLOOKUP(7,Draft!$A$2:$B$12,2,FALSE) -> Chris M | F13: Houston Texans | G13: =VLOOKUP($F13,$F$41:$U$72,G$1,FALSE) -> 12 | H13: =VLOOKUP($F13,$F$41:$U$72,H$1,FALSE) -> 9.4 | I13: =VLOOKUP($F13,$F$41:$U$72,I$1,FALSE) -> 9 | J13: =VLOOKUP($F13,$F$41:$U$72,J$1,FALSE) -> 10 | K13: =VLOOKUP($F13,$F$41:$U$72,K$1,FALSE) -> 10 | L13: =VLOOKUP($F13,$F$41:$U$72,L$1,FALSE) -> 9 | M13: =VLOOKUP($F13,$F$41:$U$72,M$1,FALSE) -> 8.9096 | N13: =VLOOKUP($F13,$F$41:$U$72,N$1,FALSE) -> 10.4 | ... U13: =VLOOKUP($F13,$F$41:$U$72,U$1,FALSE) -> 11 | V13: =IF(Table2[[#This Row],[Pick]]>=Table2[[#This Row],[Rank]],1,-1) -> 1 | W13: =Table2[[#This Row],[Pick]]-Table2[[#This Row],[Rank]] -> 0 | X13: 2 | Y13: HOU | Z13: ="2024,"&Table2[[#This Row],[Pick]]&","&Table2[[#This Row],[PlayerID]]&","&Table2[[#This Row],[T1]] -> 2024,11,2,HOU
D14: 12 | E14: =VLOOKUP(10,Draft!$A$2:$B$12,2,FALSE) -> Bailey | F14: Atlanta Falcons | G14: =VLOOKUP($F14,$F$41:$U$72,G$1,FALSE) -> 9 | H14: =VLOOKUP($F14,$F$41:$U$72,H$1,FALSE) -> 9.2 | I14: =VLOOKUP($F14,$F$41:$U$72,I$1,FALSE) -> 8 | J14: =VLOOKUP($F14,$F$41:$U$72,J$1,FALSE) -> 6 | K14: =VLOOKUP($F14,$F$41:$U$72,K$1,FALSE) -> 10 | L14: =VLOOKUP($F14,$F$41:$U$72,L$1,FALSE) -> 9.4 | M14: =VLOOKUP($F14,$F$41:$U$72,M$1,FALSE) -> 9.0563 | N14: =VLOOKUP($F14,$F$41:$U$72,N$1,FALSE) -> 10.1 | ... U14: =VLOOKUP($F14,$F$41:$U$72,U$1,FALSE) -> 14 | V14: =IF(Table2[[#This Row],[Pick]]>=Table2[[#This Row],[Rank]],1,-1) -> -1 | W14: =Table2[[#This Row],[Pick]]-Table2[[#This Row],[Rank]] -> -2 | X14: 10 | Y14: ATL | Z14: ="2024,"&Table2[[#This Row],[Pick]]&","&Table2[[#This Row],[PlayerID]]&","&Table2[[#This Row],[T1]] -> 2024,12,10,ATL
D15: 13 | E15: =VLOOKUP(3,Draft!$A$2:$B$12,2,FALSE) -> Brad | F15: Miami Dolphins | G15: =VLOOKUP($F15,$F$41:$U$72,G$1,FALSE) -> 11 | H15: =VLOOKUP($F15,$F$41:$U$72,H$1,FALSE) -> 9.2 | I15: =VLOOKUP($F15,$F$41:$U$72,I$1,FALSE) -> 9 | J15: =VLOOKUP($F15,$F$41:$U$72,J$1,FALSE) -> 9 | K15: =VLOOKUP($F15,$F$41:$U$72,K$1,FALSE) -> 11 | L15: =VLOOKUP($F15,$F$41:$U$72,L$1,FALSE) -> 9.5 | M15: =VLOOKUP($F15,$F$41:$U$72,M$1,FALSE) -> 9.141 | N15: =VLOOKUP($F15,$F$41:$U$72,N$1,FALSE) -> 10 | ... U15: =VLOOKUP($F15,$F$41:$U$72,U$1,FALSE) -> 9 | V15: =IF(Table2[[#This Row],[Pick]]>=Table2[[#This Row],[Rank]],1,-1) -> 1 | W15: =Table2[[#This Row],[Pick]]-Table2[[#This Row],[Rank]] -> 4 | X15: 3 | Y15: MIA | Z15: ="2024,"&Table2[[#This Row],[Pick]]&","&Table2[[#This Row],[PlayerID]]&","&Table2[[#This Row],[T1]] -> 2024,13,3,MIA
D16: 14 | E16: =VLOOKUP(9,Draft!$A$2:$B$12,2,FALSE) -> Avallone | F16: Los Angeles Rams | G16: =VLOOKUP($F16,$F$41:$U$72,G$1,FALSE) -> 9 | H16: =VLOOKUP($F16,$F$41:$U$72,H$1,FALSE) -> 8.7 | I16: =VLOOKUP($F16,$F$41:$U$72,I$1,FALSE) -> 11 | J16: =VLOOKUP($F16,$F$41:$U$72,J$1,FALSE) -> 9 | K16: =VLOOKUP($F16,$F$41:$U$72,K$1,FALSE) -> 12 | L16: =VLOOKUP($F16,$F$41:$U$72,L$1,FALSE) -> 8.8 | M16: =VLOOKUP($F16,$F$41:$U$72,M$1,FALSE) -> 8.5547 | N16: =VLOOKUP($F16,$F$41:$U$72,N$1,FALSE) -> 8.9 | ... U16: =VLOOKUP($F16,$F$41:$U$72,U$1,FALSE) -> 13 | V16: =IF(Table2[[#This Row],[Pick]]>=Table2[[#This Row],[Rank]],1,-1) -> 1 | W16: =Table2[[#This Row],[Pick]]-Table2[[#This Row],[Rank]] -> 1 | X16: 5 | Y16: LA | Z16: ="2024,"&Table2[[#This Row],[Pick]]&","&Table2[[#This Row],[PlayerID]]&","&Table2[[#This Row],[T1]] -> 2024,14,5,LA
D17: 15 | E17: =VLOOKUP(5,Draft!$A$2:$B$12,2,FALSE) -> Fish | F17: Los Angeles Chargers | G17: =VLOOKUP($F17,$F$41:$U$72,G$1,FALSE) -> 9 | H17: =VLOOKUP($F17,$F$41:$U$72,H$1,FALSE) -> 8.8 | I17: =VLOOKUP($F17,$F$41:$U$72,I$1,FALSE) -> 9 | J17: =VLOOKUP($F17,$F$41:$U$72,J$1,FALSE) -> 9 | K17: =VLOOKUP($F17,$F$41:$U$72,K$1,FALSE) -> 10 | L17: =VLOOKUP($F17,$F$41:$U$72,L$1,FALSE) -> 8.9 | M17: =VLOOKUP($F17,$F$41:$U$72,M$1,FALSE) -> 8.4462 | N17: =VLOOKUP($F17,$F$41:$U$72,N$1,FALSE) -> 8 | ... U17: =VLOOKUP($F17,$F$41:$U$72,U$1,FALSE) -> 16 | V17: =IF(Table2[[#This Row],[Pick]]>=Table2[[#This Row],[Rank]],1,-1) -> -1 | W17: =Table2[[#This Row],[Pick]]-Table2[[#This Row],[Rank]] -> -1 | X17: 1 | Y17: LAC | Z17: ="2024,"&Table2[[#This Row],[Pick]]&","&Table2[[#This Row],[PlayerID]]&","&Table2[[#This Row],[T1]] -> 2024,15,1,LAC
D18: 16 | E18: =VLOOKUP(2,Draft!$A$2:$B$12,2,FALSE) -> Conley | F18: Jacksonville Jaguars | G18: =VLOOKUP($F18,$F$41:$U$72,G$1,FALSE) -> 7 | H18: =VLOOKUP($F18,$F$41:$U$72,H$1,FALSE) -> 8.3 | I18: =VLOOKUP($F18,$F$41:$U$72,I$1,FALSE) -> 7 | J18: =VLOOKUP($F18,$F$41:$U$72,J$1,FALSE) -> 10 | K18: =VLOOKUP($F18,$F$41:$U$72,K$1,FALSE) -> 8 | L18: =VLOOKUP($F18,$F$41:$U$72,L$1,FALSE) -> 8.1 | M18: =VLOOKUP($F18,$F$41:$U$72,M$1,FALSE) -> 8.2482 | N18: =VLOOKUP($F18,$F$41:$U$72,N$1,FALSE) -> 8.3 | ... U18: =VLOOKUP($F18,$F$41:$U$72,U$1,FALSE) -> 19 | V18: =IF(Table2[[#This Row],[Pick]]>=Table2[[#This Row],[Rank]],1,-1) -> -1 | W18: =Table2[[#This Row],[Pick]]-Table2[[#This Row],[Rank]] -> -3 | X18: 8 | Y18: JAX | Z18: ="2024,"&Table2[[#This Row],[Pick]]&","&Table2[[#This Row],[PlayerID]]&","&Table2[[#This Row],[T1]] -> 2024,16,8,JAX
D19: 17 | E19: =VLOOKUP(8,Draft!$A$2:$B$12,2,FALSE) -> Matt M | F19: Indianapolis Colts | G19: =VLOOKUP($F19,$F$41:$U$72,G$1,FALSE) -> 9 | H19: =VLOOKUP($F19,$F$41:$U$72,H$1,FALSE) -> 8.2 | I19: =VLOOKUP($F19,$F$41:$U$72,I$1,FALSE) -> 9 | J19: =VLOOKUP($F19,$F$41:$U$72,J$1,FALSE) -> 7 | K19: =VLOOKUP($F19,$F$41:$U$72,K$1,FALSE) -> 7 | L19: =VLOOKUP($F19,$F$41:$U$72,L$1,FALSE) -> 7.5 | M19: =VLOOKUP($F19,$F$41:$U$72,M$1,FALSE) -> 8.0189 | N19: =VLOOKUP($F19,$F$41:$U$72,N$1,FALSE) -> 8.1 | ... U19: =VLOOKUP($F19,$F$41:$U$72,U$1,FALSE) -> 21 | V19: =IF(Table2[[#This Row],[Pick]]>=Table2[[#This Row],[Rank]],1,-1) -> -1 | W19: =Table2[[#This Row],[Pick]]-Table2[[#This Row],[Rank]] -> -4 | X19: 4 | Y19: IND | Z19: ="2024,"&Table2[[#This Row],[Pick]]&","&Table2[[#This Row],[PlayerID]]&","&Table2[[#This Row],[T1]] -> 2024,17,4,IND
D20: 18 | E20: =VLOOKUP(4,Draft!$A$2:$B$12,2,FALSE) -> Flaim | F20: Cleveland Browns | G20: =VLOOKUP($F20,$F$41:$U$72,G$1,FALSE) -> 8 | H20: =VLOOKUP($F20,$F$41:$U$72,H$1,FALSE) -> 8.6 | I20: =VLOOKUP($F20,$F$41:$U$72,I$1,FALSE) -> 9 | J20: =VLOOKUP($F20,$F$41:$U$72,J$1,FALSE) -> 6 | K20: =VLOOKUP($F20,$F$41:$U$72,K$1,FALSE) -> 9 | L20: =VLOOKUP($F20,$F$41:$U$72,L$1,FALSE) -> 8.7 | M20: =VLOOKUP($F20,$F$41:$U$72,M$1,FALSE) -> 8.1078 | N20: =VLOOKUP($F20,$F$41:$U$72,N$1,FALSE) -> 8.7 | ... U20: =VLOOKUP($F20,$F$41:$U$72,U$1,FALSE) -> 18 | V20: =IF(Table2[[#This Row],[Pick]]>=Table2[[#This Row],[Rank]],1,-1) -> 1 | W20: =Table2[[#This Row],[Pick]]-Table2[[#This Row],[Rank]] -> 0 | X20: 7 | Y20: CLE | Z20: ="2024,"&Table2[[#This Row],[Pick]]&","&Table2[[#This Row],[PlayerID]]&","&Table2[[#This Row],[T1]] -> 2024,18,7,CLE
D21: 19 | E21: =VLOOKUP(6,Draft!$A$2:$B$12,2,FALSE) -> Rubino | F21: Tampa Bay Buccaneers | G21: =VLOOKUP($F21,$F$41:$U$72,G$1,FALSE) -> 8 | H21: =VLOOKUP($F21,$F$41:$U$72,H$1,FALSE) -> 8.1 | I21: =VLOOKUP($F21,$F$41:$U$72,I$1,FALSE) -> 9 | J21: =VLOOKUP($F21,$F$41:$U$72,J$1,FALSE) -> 10 | K21: =VLOOKUP($F21,$F$41:$U$72,K$1,FALSE) -> 8 | L21: =VLOOKUP($F21,$F$41:$U$72,L$1,FALSE) -> 7.5 | M21: =VLOOKUP($F21,$F$41:$U$72,M$1,FALSE) -> 8.1047 | N21: =VLOOKUP($F21,$F$41:$U$72,N$1,FALSE) -> 8 | ... U21: =VLOOKUP($F21,$F$41:$U$72,U$1,FALSE) -> 20 | V21: =IF(Table2[[#This Row],[Pick]]>=Table2[[#This Row],[Rank]],1,-1) -> -1 | W21: =Table2[[#This Row],[Pick]]-Table2[[#This Row],[Rank]] -> -1 | X21: 9 | Y21: TB | Z21: ="2024,"&Table2[[#This Row],[Pick]]&","&Table2[[#This Row],[PlayerID]]&","&Table2[[#This Row],[T1]] -> 2024,19,9,TB
D22: 20 | E22: =VLOOKUP(1,Draft!$A$2:$B$12,2,FALSE) -> Otto | F22: Las Vegas Raiders | G22: =VLOOKUP($F22,$F$41:$U$72,G$1,FALSE) -> 8 | H22: =VLOOKUP($F22,$F$41:$U$72,H$1,FALSE) -> 7.2 | I22: =VLOOKUP($F22,$F$41:$U$72,I$1,FALSE) -> 6 | J22: =VLOOKUP($F22,$F$41:$U$72,J$1,FALSE) -> 7 | K22: =VLOOKUP($F22,$F$41:$U$72,K$1,FALSE) -> 6 | L22: =VLOOKUP($F22,$F$41:$U$72,L$1,FALSE) -> 7.3 | M22: =VLOOKUP($F22,$F$41:$U$72,M$1,FALSE) -> 7.4429 | N22: =VLOOKUP($F22,$F$41:$U$72,N$1,FALSE) -> 5.7 | ... U22: =VLOOKUP($F22,$F$41:$U$72,U$1,FALSE) -> 26 | V22: =IF(Table2[[#This Row],[Pick]]>=Table2[[#This Row],[Rank]],1,-1) -> -1 | W22: =Table2[[#This Row],[Pick]]-Table2[[#This Row],[Rank]] -> -6 | X22: 6 | Y22: LV | Z22: ="2024,"&Table2[[#This Row],[Pick]]&","&Table2[[#This Row],[PlayerID]]&","&Table2[[#This Row],[T1]] -> 2024,20,6,LV
D23: 21 | E23: =VLOOKUP(8,Draft!$A$2:$B$12,2,FALSE) -> Matt M | F23: Pittsburgh Steelers | G23: =VLOOKUP($F23,$F$41:$U$72,G$1,FALSE) -> 10 | H23: =VLOOKUP($F23,$F$41:$U$72,H$1,FALSE) -> 8 | I23: =VLOOKUP($F23,$F$41:$U$72,I$1,FALSE) -> 10 | J23: =VLOOKUP($F23,$F$41:$U$72,J$1,FALSE) -> 8 | K23: =VLOOKUP($F23,$F$41:$U$72,K$1,FALSE) -> 8 | L23: =VLOOKUP($F23,$F$41:$U$72,L$1,FALSE) -> 7.6 | M23: =VLOOKUP($F23,$F$41:$U$72,M$1,FALSE) -> 8.0217 | N23: =VLOOKUP($F23,$F$41:$U$72,N$1,FALSE) -> 8.6 | ... U23: =VLOOKUP($F23,$F$41:$U$72,U$1,FALSE) -> 17 | V23: =IF(Table2[[#This Row],[Pick]]>=Table2[[#This Row],[Rank]],1,-1) -> 1 | W23: =Table2[[#This Row],[Pick]]-Table2[[#This Row],[Rank]] -> 4 | X23: 4 | Y23: PIT | Z23: ="2024,"&Table2[[#This Row],[Pick]]&","&Table2[[#This Row],[PlayerID]]&","&Table2[[#This Row],[T1]] -> 2024,21,4,PIT
D24: 22 | E24: =VLOOKUP(6,Draft!$A$2:$B$12,2,FALSE) -> Rubino | F24: Chicago Bears | G24: =VLOOKUP($F24,$F$41:$U$72,G$1,FALSE) -> 10 | H24: =VLOOKUP($F24,$F$41:$U$72,H$1,FALSE) -> 8.8 | I24: =VLOOKUP($F24,$F$41:$U$72,I$1,FALSE) -> 9 | J24: =VLOOKUP($F24,$F$41:$U$72,J$1,FALSE) -> 10 | K24: =VLOOKUP($F24,$F$41:$U$72,K$1,FALSE) -> 8 | L24: =VLOOKUP($F24,$F$41:$U$72,L$1,FALSE) -> 8.1 | M24: =VLOOKUP($F24,$F$41:$U$72,M$1,FALSE) -> 8.6811 | N24: =VLOOKUP($F24,$F$41:$U$72,N$1,FALSE) -> 8.6 | ... U24: =VLOOKUP($F24,$F$41:$U$72,U$1,FALSE) -> 15 | V24: =IF(Table2[[#This Row],[Pick]]>=Table2[[#This Row],[Rank]],1,-1) -> 1 | W24: =Table2[[#This Row],[Pick]]-Table2[[#This Row],[Rank]] -> 7 | X24: 9 | Y24: CHI | Z24: ="2024,"&Table2[[#This Row],[Pick]]&","&Table2[[#This Row],[PlayerID]]&","&Table2[[#This Row],[T1]] -> 2024,22,9,CHI
D25: 23 | E25: =VLOOKUP(9,Draft!$A$2:$B$12,2,FALSE) -> Avallone | F25: Arizona Cardinals | G25: =VLOOKUP($F25,$F$41:$U$72,G$1,FALSE) -> 6 | H25: =VLOOKUP($F25,$F$41:$U$72,H$1,FALSE) -> 7.6 | I25: =VLOOKUP($F25,$F$41:$U$72,I$1,FALSE) -> 9 | J25: =VLOOKUP($F25,$F$41:$U$72,J$1,FALSE) -> 7 | K25: =VLOOKUP($F25,$F$41:$U$72,K$1,FALSE) -> 6 | L25: =VLOOKUP($F25,$F$41:$U$72,L$1,FALSE) -> 7.1 | M25: =VLOOKUP($F25,$F$41:$U$72,M$1,FALSE) -> 7.1859 | N25: =VLOOKUP($F25,$F$41:$U$72,N$1,FALSE) -> 6.9 | ... U25: =VLOOKUP($F25,$F$41:$U$72,U$1,FALSE) -> 24 | V25: =IF(Table2[[#This Row],[Pick]]>=Table2[[#This Row],[Rank]],1,-1) -> -1 | W25: =Table2[[#This Row],[Pick]]-Table2[[#This Row],[Rank]] -> -1 | X25: 5 | Y25: ARI | Z25: ="2024,"&Table2[[#This Row],[Pick]]&","&Table2[[#This Row],[PlayerID]]&","&Table2[[#This Row],[T1]] -> 2024,23,5,ARI
D26: 24 | E26: =VLOOKUP(10,Draft!$A$2:$B$12,2,FALSE) -> Bailey | F26: Seattle Seahawks | G26: =VLOOKUP($F26,$F$41:$U$72,G$1,FALSE) -> 7 | H26: =VLOOKUP($F26,$F$41:$U$72,H$1,FALSE) -> 8.3 | I26: =VLOOKUP($F26,$F$41:$U$72,I$1,FALSE) -> 6 | J26: =VLOOKUP($F26,$F$41:$U$72,J$1,FALSE) -> 9 | K26: =VLOOKUP($F26,$F$41:$U$72,K$1,FALSE) -> 7 | L26: =VLOOKUP($F26,$F$41:$U$72,L$1,FALSE) -> 8.2 | M26: =VLOOKUP($F26,$F$41:$U$72,M$1,FALSE) -> 7.889 | N26: =VLOOKUP($F26,$F$41:$U$72,N$1,FALSE) -> 8.5 | ... U26: =VLOOKUP($F26,$F$41:$U$72,U$1,FALSE) -> 22 | V26: =IF(Table2[[#This Row],[Pick]]>=Table2[[#This Row],[Rank]],1,-1) -> 1 | W26: =Table2[[#This Row],[Pick]]-Table2[[#This Row],[Rank]] -> 2 | X26: 10 | Y26: SEA | Z26: ="2024,"&Table2[[#This Row],[Pick]]&","&Table2[[#This Row],[PlayerID]]&","&Table2[[#This Row],[T1]] -> 2024,24,10,SEA
D27: 25 | E27: =VLOOKUP(4,Draft!$A$2:$B$12,2,FALSE) -> Flaim | F27: New Orleans Saints | G27: =VLOOKUP($F27,$F$41:$U$72,G$1,FALSE) -> 7 | H27: =VLOOKUP($F27,$F$41:$U$72,H$1,FALSE) -> 7.7 | I27: =VLOOKUP($F27,$F$41:$U$72,I$1,FALSE) -> 8 | J27: =VLOOKUP($F27,$F$41:$U$72,J$1,FALSE) -> 7 | K27: =VLOOKUP($F27,$F$41:$U$72,K$1,FALSE) -> 6 | L27: =VLOOKUP($F27,$F$41:$U$72,L$1,FALSE) -> 8.2 | M27: =VLOOKUP($F27,$F$41:$U$72,M$1,FALSE) -> 8.1506 | N27: =VLOOKUP($F27,$F$41:$U$72,N$1,FALSE) -> 7.4 | ... U27: =VLOOKUP($F27,$F$41:$U$72,U$1,FALSE) -> 23 | V27: =IF(Table2[[#This Row],[Pick]]>=Table2[[#This Row],[Rank]],1,-1) -> 1 | W27: =Table2[[#This Row],[Pick]]-Table2[[#This Row],[Rank]] -> 2 | X27: 7 | Y27: NO | Z27: ="2024,"&Table2[[#This Row],[Pick]]&","&Table2[[#This Row],[PlayerID]]&","&Table2[[#This Row],[T1]] -> 2024,25,7,NO
D28: 26 | E28: =VLOOKUP(1,Draft!$A$2:$B$12,2,FALSE) -> Otto | F28: Tennessee Titans | G28: =VLOOKUP($F28,$F$41:$U$72,G$1,FALSE) -> 5 | H28: =VLOOKUP($F28,$F$41:$U$72,H$1,FALSE) -> 6.8 | I28: =VLOOKUP($F28,$F$41:$U$72,I$1,FALSE) -> 6 | J28: =VLOOKUP($F28,$F$41:$U$72,J$1,FALSE) -> 5 | K28: =VLOOKUP($F28,$F$41:$U$72,K$1,FALSE) -> 6 | L28: =VLOOKUP($F28,$F$41:$U$72,L$1,FALSE) -> 6.8 | M28: =VLOOKUP($F28,$F$41:$U$72,M$1,FALSE) -> 7.1442 | N28: =VLOOKUP($F28,$F$41:$U$72,N$1,FALSE) -> 6.2 | ... U28: =VLOOKUP($F28,$F$41:$U$72,U$1,FALSE) -> 28 | V28: =IF(Table2[[#This Row],[Pick]]>=Table2[[#This Row],[Rank]],1,-1) -> -1 | W28: =Table2[[#This Row],[Pick]]-Table2[[#This Row],[Rank]] -> -2 | X28: 6 | Y28: TEN | Z28: ="2024,"&Table2[[#This Row],[Pick]]&","&Table2[[#This Row],[PlayerID]]&","&Table2[[#This Row],[T1]] -> 2024,26,6,TEN
D29: 27 | E29: =VLOOKUP(5,Draft!$A$2:$B$12,2,FALSE) -> Fish | F29: Minnesota Vikings | G29: =VLOOKUP($F29,$F$41:$U$72,G$1,FALSE) -> 8 | H29: =VLOOKUP($F29,$F$41:$U$72,H$1,FALSE) -> 7.5 | I29: =VLOOKUP($F29,$F$41:$U$72,I$1,FALSE) -> 7 | J29: =VLOOKUP($F29,$F$41:$U$72,J$1,FALSE) -> 4 | K29: =VLOOKUP($F29,$F$41:$U$72,K$1,FALSE) -> 6 | L29: =VLOOKUP($F29,$F$41:$U$72,L$1,FALSE) -> 6.8 | M29: =VLOOKUP($F29,$F$41:$U$72,M$1,FALSE) -> 7.6951 | N29: =VLOOKUP($F29,$F$41:$U$72,N$1,FALSE) -> 7 | ... U29: =VLOOKUP($F29,$F$41:$U$72,U$1,FALSE) -> 25 | V29: =IF(Table2[[#This Row],[Pick]]>=Table2[[#This Row],[Rank]],1,-1) -> 1 | W29: =Table2[[#This Row],[Pick]]-Table2[[#This Row],[Rank]] -> 2 | X29: 1 | Y29: MIN | Z29: ="2024,"&Table2[[#This Row],[Pick]]&","&Table2[[#This Row],[PlayerID]]&","&Table2[[#This Row],[T1]] -> 2024,27,1,MIN
D30: 28 | E30: =VLOOKUP(7,Draft!$A$2:$B$12,2,FALSE) -> Chris M | F30: Washington Commanders | G30: =VLOOKUP($F30,$F$41:$U$72,G$1,FALSE) -> 7 | H30: =VLOOKUP($F30,$F$41:$U$72,H$1,FALSE) -> 7.2 | I30: =VLOOKUP($F30,$F$41:$U$72,I$1,FALSE) -> 6 | J30: =VLOOKUP($F30,$F$41:$U$72,J$1,FALSE) -> 5 | K30: =VLOOKUP($F30,$F$41:$U$72,K$1,FALSE) -> 7 | L30: =VLOOKUP($F30,$F$41:$U$72,L$1,FALSE) -> 5.9 | M30: =VLOOKUP($F30,$F$41:$U$72,M$1,FALSE) -> 7.2245 | N30: =VLOOKUP($F30,$F$41:$U$72,N$1,FALSE) -> 6.4 | ... U30: =VLOOKUP($F30,$F$41:$U$72,U$1,FALSE) -> 27 | V30: =IF(Table2[[#This Row],[Pick]]>=Table2[[#This Row],[Rank]],1,-1) -> 1 | W30: =Table2[[#This Row],[Pick]]-Table2[[#This Row],[Rank]] -> 1 | X30: 2 | Y30: WAS | Z30: ="2024,"&Table2[[#This Row],[Pick]]&","&Table2[[#This Row],[PlayerID]]&","&Table2[[#This Row],[T1]] -> 2024,28,2,WAS
D31: 29 | E31: =VLOOKUP(2,Draft!$A$2:$B$12,2,FALSE) -> Conley | F31: Denver Broncos | G31: =VLOOKUP($F31,$F$41:$U$72,G$1,FALSE) -> 5 | H31: =VLOOKUP($F31,$F$41:$U$72,H$1,FALSE) -> 6.6 | I31: =VLOOKUP($F31,$F$41:$U$72,I$1,FALSE) -> 5 | J31: =VLOOKUP($F31,$F$41:$U$72,J$1,FALSE) -> 8 | K31: =VLOOKUP($F31,$F$41:$U$72,K$1,FALSE) -> 7 | L31: =VLOOKUP($F31,$F$41:$U$72,L$1,FALSE) -> 6 | M31: =VLOOKUP($F31,$F$41:$U$72,M$1,FALSE) -> 7.053 | N31: =VLOOKUP($F31,$F$41:$U$72,N$1,FALSE) -> 6.4 | ... U31: =VLOOKUP($F31,$F$41:$U$72,U$1,FALSE) -> 29 | V31: =IF(Table2[[#This Row],[Pick]]>=Table2[[#This Row],[Rank]],1,-1) -> 1 | W31: =Table2[[#This Row],[Pick]]-Table2[[#This Row],[Rank]] -> 0 | X31: 8 | Y31: DEN | Z31: ="2024,"&Table2[[#This Row],[Pick]]&","&Table2[[#This Row],[PlayerID]]&","&Table2[[#This Row],[T1]] -> 2024,29,8,DEN
D32: 30 | E32: =VLOOKUP(3,Draft!$A$2:$B$12,2,FALSE) -> Brad | F32: New York Giants | G32: =VLOOKUP($F32,$F$41:$U$72,G$1,FALSE) -> 4 | H32: =VLOOKUP($F32,$F$41:$U$72,H$1,FALSE) -> 6.9 | I32: =VLOOKUP($F32,$F$41:$U$72,I$1,FALSE) -> 8 | J32: =VLOOKUP($F32,$F$41:$U$72,J$1,FALSE) -> 6 | K32: =VLOOKUP($F32,$F$41:$U$72,K$1,FALSE) -> 6 | L32: =VLOOKUP($F32,$F$41:$U$72,L$1,FALSE) -> 6.7 | M32: =VLOOKUP($F32,$F$41:$U$72,M$1,FALSE) -> 7.1874 | N32: =VLOOKUP($F32,$F$41:$U$72,N$1,FALSE) -> 5.8 | ... U32: =VLOOKUP($F32,$F$41:$U$72,U$1,FALSE) -> 30 | V32: =IF(Table2[[#This Row],[Pick]]>=Table2[[#This Row],[Rank]],1,-1) -> 1 | W32: =Table2[[#This Row],[Pick]]-Table2[[#This Row],[Rank]] -> 0 | X32: 3 | Y32: NYG | Z32: ="2024,"&Table2[[#This Row],[Pick]]&","&Table2[[#This Row],[PlayerID]]&","&Table2[[#This Row],[T1]] -> 2024,30,3,NYG
D40: Pick # | E40: Picked | F40: Team | G40: BR | H40: FPI | I40: SI | J40: ESPN | K40: CBS | L40: Athletic | M40: PFF | N40: NFL | O40: O/U | P40: Clay | Q40: Avg | R40: SD | S40: Z Score | T40: Z Test | U40: Rank
D41: =_xlfn.IFNA(INDEX($D$3:$F$32,MATCH($F41,$F$3:$F$32,0),1),"") -> 1 | E41: =IF(COUNTIF($F$3:$F$32,$F41)>0,"x","") -> x | F41: Kansas City Chiefs | G41: 11 | H41: 10.4 | I41: 11 | J41: 13 | K41: 12 | L41: 11.3 | M41: 10.9056 | N41: 11.4 | O41: 11.5 | P41: 11.4 | Q41: =AVERAGE(G41:P41) -> 11.39056 | R41: =_xlfn.STDEV.P(G41:P41) -> 0.67108421 | S41: =(Table_1[[#This Row],[Avg]]-$X$41)/$X$42 -> 1.4703236 | T41: =_xlfn.Z.TEST(Table_1[[#This Row],[BR]:[O/U]],Table_1[[#This Row],[BR]])+_xlfn.Z.TEST(Table_1[[#This Row],[BR]:[O/U]],Table_1[[#This Row],[FPI]])+_xlfn.Z.TEST(Table_1[[#This Row],[BR]:[O/U]],Table_1[[#This Row],[SI]])+_xlfn.Z.TEST(Table_1[[#This Row],[BR]:[O/U]],Table_1[[#This Row],[ESPN]])+_xlfn.Z.TEST(Table_1[[#This Row],[BR]:[O/U]],Table_1[[#This Row],[CBS]])+_xlfn.Z.TEST(Table_1[[#This Row],[BR]:[O/U]],Table_1[[#This Row],[Athletic]])+_xlfn.Z.TEST(Table_1[[#This Row],[BR]:[O/U]],Table_1[[#This Row],[NFL]])+_xlfn.Z.TEST(Table_1[[#This Row],[BR]:[O/U]],Table_1[[#This Row],[O/U]]) -> 3.65969 | U41: =_xlfn.RANK.EQ(Draft!Q41,Draft!$Q$41:$Q$72) -> 1 | X41: =AVERAGE(Table_1[[BR]:[Clay]]) -> 8.4925
D42: =_xlfn.IFNA(INDEX($D$3:$F$32,MATCH($F42,$F$3:$F$32,0),1),"") -> 4 | E42: =IF(COUNTIF($F$3:$F$32,$F42)>0,"x","") -> x | F42: Detroit Lions | G42: 13 | H42: 9.9 | I42: 12 | J42: 13 | K42: 12 | L42: 10.5 | M42: 9.7087 | N42: 10.7 | O42: 10.5 | P42: 10.7 | Q42: =AVERAGE(G42:P42) -> 11.20087 | R42: =_xlfn.STDEV.P(G42:P42) -> 1.1469075 | S42: =(Table_1[[#This Row],[Avg]]-$X$41)/$X$42 -> 1.3740849 | T42: =_xlfn.Z.TEST(Table_1[[#This Row],[BR]:[O/U]],Table_1[[#This Row],[BR]])+_xlfn.Z.TEST(Table_1[[#This Row],[BR]:[O/U]],Table_1[[#This Row],[FPI]])+_xlfn.Z.TEST(Table_1[[#This Row],[BR]:[O/U]],Table_1[[#This Row],[SI]])+_xlfn.Z.TEST(Table_1[[#This Row],[BR]:[O/U]],Table_1[[#This Row],[ESPN]])+_xlfn.Z.TEST(Table_1[[#This Row],[BR]:[O/U]],Table_1[[#This Row],[CBS]])+_xlfn.Z.TEST(Table_1[[#This Row],[BR]:[O/U]],Table_1[[#This Row],[Athletic]])+_xlfn.Z.TEST(Table_1[[#This Row],[BR]:[O/U]],Table_1[[#This Row],[NFL]])+_xlfn.Z.TEST(Table_1[[#This Row],[BR]:[O/U]],Table_1[[#This Row],[O/U]]) -> 4.0896037 | U42: =_xlfn.RANK.EQ(Draft!Q42,Draft!$Q$41:$Q$72) -> 2 | X42: =_xlfn.STDEV.P(Table_1[[BR]:[Clay]]) -> 1.9710354
D43: =_xlfn.IFNA(INDEX($D$3:$F$32,MATCH($F43,$F$3:$F$32,0),1),"") -> 3 | E43: =IF(COUNTIF($F$3:$F$32,$F43)>0,"x","") -> x | F43: San Francisco 49ers | G43: 11 | H43: 10.4 | I43: 10 | J43: 10 | K43: 11 | L43: 11.4 | M43: 10.6623 | N43: 11 | O43: 11.5 | P43: 12.3 | Q43: =AVERAGE(G43:P43) -> 10.92623 | R43: =_xlfn.STDEV.P(G43:P43) -> 0.67228128 | S43: =(Table_1[[#This Row],[Avg]]-$X$41)/$X$42 -> 1.234747 | T43: =_xlfn.Z.TEST(Table_1[[#This Row],[BR]:[O/U]],Table_1[[#This Row],[BR]])+_xlfn.Z.TEST(Table_1[[#This Row],[BR]:[O/U]],Table_1[[#This Row],[FPI]])+_xlfn.Z.TEST(Table_1[[#This Row],[BR]:[O/U]],Table_1[[#This Row],[SI]])+_xlfn.Z.TEST(Table_1[[#This Row],[BR]:[O/U]],Table_1[[#This Row],[ESPN]])+_xlfn.Z.TEST(Table_1[[#This Row],[BR]:[O/U]],Table_1[[#This Row],[CBS]])+_xlfn.Z.TEST(Table_1[[#This Row],[BR]:[O/U]],Table_1[[#This Row],[Athletic]])+_xlfn.Z.TEST(Table_1[[#This Row],[BR]:[O/U]],Table_1[[#This Row],[NFL]])+_xlfn.Z.TEST(Table_1[[#This Row],[BR]:[O/U]],Table_1[[#This Row],[O/U]]) -> 4.6948671 | U43: =_xlfn.RANK.EQ(Draft!Q43,Draft!$Q$41:$Q$72) -> 3
D44: =_xlfn.IFNA(INDEX($D$3:$F$32,MATCH($F44,$F$3:$F$32,0),1),"") -> 5 | E44: =IF(COUNTIF($F$3:$F$32,$F44)>0,"x","") -> x | F44: Baltimore Ravens | G44: 11 | H44: 9.7 | I44: 10 | J44: 11 | K44: 12 | L44: 10.2 | M44: 10.2175 | N44: 10.5 | O44: 10.5 | P44: 11.3 | Q44: =AVERAGE(G44:P44) -> 10.64175 | R44: =_xlfn.STDEV.P(G44:P44) -> 0.651834 | S44: =(Table_1[[#This Row],[Avg]]-$X$41)/$X$42 -> 1.0904167 | T44: =_xlfn.Z.TEST(Table_1[[#This Row],[BR]:[O/U]],Table_1[[#This Row],[BR]])+_xlfn.Z.TEST(Table_1[[#This Row],[BR]:[O/U]],Table_1[[#This Row],[FPI]])+_xlfn.Z.TEST(Table_1[[#This Row],[BR]:[O/U]],Table_1[[#This Row],[SI]])+_xlfn.Z.TEST(Table_1[[#This Row],[BR]:[O/U]],Table_1[[#This Row],[ESPN]])+_xlfn.Z.TEST(Table_1[[#This Row],[BR]:[O/U]],Table_1[[#This Row],[CBS]])+_xlfn.Z.TEST(Table_1[[#This Row],[BR]:[O/U]],Table_1[[#This Row],[Athletic]])+_xlfn.Z.TEST(Table_1[[#This Row],[BR]:[O/U]],Table_1[[#This Row],[NFL]])+_xlfn.Z.TEST(Table_1[[#This Row],[BR]:[O/U]],Table_1[[#This Row],[O/U]]) -> 3.7649889 | U44: =_xlfn.RANK.EQ(Draft!Q44,Draft!$Q$41:$Q$72) -> 4
D45: =_xlfn.IFNA(INDEX($D$3:$F$32,MATCH($F45,$F$3:$F$32,0),1),"") -> 10 | E45: =IF(COUNTIF($F$3:$F$32,$F45)>0,"x","") -> x | F45: Cincinnati Bengals | G45: 11 | H45: 9.8 | I45: 11 | J45: 11 | K45: 11 | L45: 10.2 | M45: 9.7654 | N45: 10.4 | O45: 10.5 | P45: 10.3 | Q45: =AVERAGE(G45:P45) -> 10.49654 | R45: =_xlfn.STDEV.P(G45:P45) -> 0.46578079 | S45: =(Table_1[[#This Row],[Avg]]-$X$41)/$X$42 -> 1.0167448 | T45: =_xlfn.Z.TEST(Table_1[[#This Row],[BR]:[O/U]],Table_1[[#This Row],[BR]])+_xlfn.Z.TEST(Table_1[[#This Row],[BR]:[O/U]],Table_1[[#This Row],[FPI]])+_xlfn.Z.TEST(Table_1[[#This Row],[BR]:[O/U]],Table_1[[#This Row],[SI]])+_xlfn.Z.TEST(Table_1[[#This Row],[BR]:[O/U]],Table_1[[#This Row],[ESPN]])+_xlfn.Z.TEST(Table_1[[#This Row],[BR]:[O/U]],Table_1[[#This Row],[CBS]])+_xlfn.Z.TEST(Table_1[[#This Row],[BR]:[O/U]],Table_1[[#This Row],[Athletic]])+_xlfn.Z.TEST(Table_1[[#This Row],[BR]:[O/U]],Table_1[[#This Row],[NFL]])+_xlfn.Z.TEST(Table_1[[#This Row],[BR]:[O/U]],Table_1[[#This Row],[O/U]]) -> 4.7247392 | U45: =_xlfn.RANK.EQ(Draft!Q45,Draft!$Q$41:$Q$72) -> 5
D46: =_xlfn.IFNA(INDEX($D$3:$F$32,MATCH($F46,$F$3:$F$32,0),1),"") -> 8 | E46: =IF(COUNTIF($F$3:$F$32,$F46)>0,"x","") -> x | F46: Philadelphia Eagles | G46: 12 | H46: 10.3 | I46: 10 | J46: 11 | K46: 9 | L46: 10.2 | M46: 9.7891 | N46: 11.2 | O46: 10.5 | P46: 9.8 | Q46: =AVERAGE(G46:P46) -> 10.37891 | R46: =_xlfn.STDEV.P(G46:P46) -> 0.80428545 | S46: =(Table_1[[#This Row],[Avg]]-$X$41)/$X$42 -> 0.95706549 | T46: =_xlfn.Z.TEST(Table_1[[#This Row],[BR]:[O/U]],Table_1[[#This Row],[BR]])+_xlfn.Z.TEST(Table_1[[#This Row],[BR]:[O/U]],Table_1[[#This Row],[FPI]])+_xlfn.Z.TEST(Table_1[[#This Row],[BR]:[O/U]],Table_1[[#This Row],[SI]])+_xlfn.Z.TEST(Table_1[[#This Row],[BR]:[O/U]],Table_1[[#This Row],[ESPN]])+_xlfn.Z.TEST(Table_1[[#This Row],[BR]:[O/U]],Table_1[[#This Row],[CBS]])+_xlfn.Z.TEST(Table_1[[#This Row],[BR]:[O/U]],Table_1[[#This Row],[Athletic]])+_xlfn.Z.TEST(Table_1[[#This Row],[BR]:[O/U]],Table_1[[#This Row],[NFL]])+_xlfn.Z.TEST(Table_1[[#This Row],[BR]:[O/U]],Table_1[[#This Row],[O/U]]) -> 4.1215702 | U46: =_xlfn.RANK.EQ(Draft!Q46,Draft!$Q$41:$Q$72) -> 6
D47: =_xlfn.IFNA(INDEX($D$3:$F$32,MATCH($F47,$F$3:$F$32,0),1),"") -> 6 | E47: =IF(COUNTIF($F$3:$F$32,$F47)>0,"x","") -> x | F47: Green Bay Packers | G47: 10 | H47: 9.2 | I47: 12 | J47: 11 | K47: 11 | L47: 9.8 | M47: 9.2241 | N47: 9.8 | O47: 9.5 | P47: 9 | Q47: =AVERAGE(G47:P47) -> 10.05241 | R47: =_xlfn.STDEV.P(G47:P47) -> 0.9243675 | S47: =(Table_1[[#This Row],[Avg]]-$X$41)/$X$42 -> 0.79141652 | T47: =_xlfn.Z.TEST(Table_1[[#This Row],[BR]:[O/U]],Table_1[[#This Row],[BR]])+_xlfn.Z.TEST(Table_1[[#This Row],[BR]:[O/U]],Table_1[[#This Row],[FPI]])+_xlfn.Z.TEST(Table_1[[#This Row],[BR]:[O/U]],Table_1[[#This Row],[SI]])+_xlfn.Z.TEST(Table_1[[#This Row],[BR]:[O/U]],Table_1[[#This Row],[ESPN]])+_xlfn.Z.TEST(Table_1[[#This Row],[BR]:[O/U]],Table_1[[#This Row],[CBS]])+_xlfn.Z.TEST(Table_1[[#This Row],[BR]:[O/U]],Table_1[[#This Row],[Athletic]])+_xlfn.Z.TEST(Table_1[[#This Row],[BR]:[O/U]],Table_1[[#This Row],[NFL]])+_xlfn.Z.TEST(Table_1[[#This Row],[BR]:[O/U]],Table_1[[#This Row],[O/U]]) -> 3.5540012 | U47: =_xlfn.RANK.EQ(Draft!Q47,Draft!$Q$41:$Q$72) -> 7
...

Sheet DraftOrder
A1: Pick | B1: Pick1 | C1: Pick2 | D1: Pick3
A2: 1 | B2: 1 | C2: 20 | D2: 26
A3: 2 | B3: 2 | C3: 16 | D3: 29
A4: 3 | B4: 3 | C4: 13 | D4: 30
A5: 4 | B5: 4 | C5: 18 | D5: 25
A6: 5 | B6: 5 | C6: 15 | D6: 27
A7: 6 | B7: 6 | C7: 19 | D7: 22
A8: 7 | B8: 7 | C8: 11 | D8: 28
A9: 8 | B9: 8 | C9: 17 | D9: 21
A10: 9 | B10: 9 | C10: 14 | D10: 23
A11: 10 | B11: 10 | C11: 12 | D11: 24
